Workbook

Sheet L. COMPRAS
L1: RUT EMPRESA | M1: 76.123.456-0
D2: LIBRO DE COMPRAS | L2: Silvestres del Ñuble SpA (ficticia)
A3: MES: OCTUBRE 2026 | H3: 10
A5: FECHA | B5: Nº DE | C5: NOMBRE DEL | D5: RUT | E5: EXENTO | F5: GASTOS | G5: ACTIVO | H5: NETO | I5: IVA | J5: TOTAL | K5: IVA RETENIDO TOTAL (cód. 31 silvestres) | L5: TOTAL FACTURAS MDS | O5: =H31
B6: DOCUMENTO | C6: PROVEEDOR | F6: GENERALES | G6: FIJO | L6: TOTAL FACTURAS GASTOS GENERALES | O6: =F31
A7: 46297 | B7: 201 | C7: Juan Pérez (recolector) | D7: 11.111.111-1 | H7: ='Facturas de compra'!H5 | I7: ='Facturas de compra'!I5 | J7: =H7+I7 | K7: ='Facturas de compra'!J5 | L7: TOTAL FACTURAS ACTIVO FIJO | O7: =G31
A8: 46301 | B8: 202 | C8: María Soto (recolectora) | D8: 12.222.222-5 | H8: ='Facturas de compra'!H6 | I8: ='Facturas de compra'!I6 | J8: =H8+I8 | K8: ='Facturas de compra'!J6
A9: 46307 | B9: 203 | C9: Pedro Núñez (recolector) | D9: 13.333.333-9 | H9: ='Facturas de compra'!H7 | I9: ='Facturas de compra'!I7 | J9: =H9+I9 | K9: ='Facturas de compra'!J7 | L9: ASIENTO CONTABLE POR LAS COMPRAS
A10: 46314 | B10: 204 | C10: Rosa Muñoz (recolectora) | D10: 14.444.444-2 | H10: ='Facturas de compra'!H8 | I10: ='Facturas de compra'!I8 | J10: =H10+I10 | K10: ='Facturas de compra'!J8
A11: 46321 | B11: 205 | C11: Luis Araya (recolector) | D11: 15.555.555-6 | H11: ='Facturas de compra'!H9 | I11: ='Facturas de compra'!I9 | J11: =H11+I11 | K11: ='Facturas de compra'!J9 | L11: MERCADERIAS | N11: =O5
L12: MERCADERIAS EXENTAS | N12: =E31
L13: GASTOS GENERALES | N13: =O6
L14: ACTIVO FIJO | N14: =O7
L15: CREDITO FISCAL | N15: =I31
M16: PROVEEDORES | O16: =J31-K31
M17: IVA RETENIDO POR PAGAR | O17: =K31
L18: Por las compras del mes
L19: Verificación proceso | M19: Verificación (debe = haber) | N19: =SUM(N11:N15) | O19: =SUM(O16:O17)
C31: SUMAS | E31: =SUM(E7:E30) | F31: =SUM(F7:F30) | G31: =SUM(G7:G30) | H31: =SUM(H7:H30) | I31: =SUM(I7:I30) | J31: =SUM(J7:J30) | K31: =SUM(K7:K30)
A34: ( + ) NOTAS DE DEBITO
C47: SUMAS
A50: ( - ) NOTAS DE CREDITO
C62: SUMAS
C64: TOTAL COMPRAS AFECTAS | H64: =H31+H47-H62 | I64: =I31+I47-I62
A66: Las facturas de compra (DTE 46) las emite el comprador; su IVA es crédito fiscal (Res. 4095, N° 6) y el IVA retenido se paga en el F29 (reverso, código 39). Código 31 = IVA retenido silvestres (se informa como retención total).

Sheet L. VENTAS
B2: Silvestres del Ñuble SpA (ficticia) | E2: LIBRO VENTAS
B3: AÑO: | C3: 2026
B4: FECHA | C4: FACTURA Nº | D4: VENTAS CON | E4: VENTAS | F4: CLIENTE | G4: RUT | H4: NETO | I4: IVA | J4: TOTAL | M4: ultima boleta emitida | O4: 0
C5: BOLETAS DEL/ HASTA | D5: BOLETAS | E5: EXENTAS | I5: 0.19 | M5: primera boleta emitida | O5: 0
B6: 46300 | C6: 101 | F6: Exportadora Andes SpA | G6: 76.200.100-4 | H6: 1900000 | I6: =ROUND(H6*$I$5,0) | J6: =H6+I6
B7: 46304 | C7: 102 | F7: Agroindustrial Sur Ltda. | G7: 76.200.200-0 | H7: 1500000 | I7: =ROUND(H7*$I$5,0) | J7: =H7+I7
B8: 46309 | C8: 103 | F8: Hierbas del Valle S.A. | G8: 76.200.300-7 | H8: 1400000 | I8: =ROUND(H8*$I$5,0) | J8: =H8+I8 | M8: ultima factura emitida | O8: 105
B9: 46316 | C9: 104 | F9: Comercial Maule SpA | G9: 76.200.400-3 | H9: 900000 | I9: =ROUND(H9*$I$5,0) | J9: =H9+I9 | M9: primera factura emitida | O9: 101
B10: 46323 | C10: 105 | F10: Distribuidora Bío Bío Ltda. | G10: 76.200.500-K | H10: 1300000 | I10: =ROUND(H10*$I$5,0) | J10: =H10+I10
M12: CAJA | P12: =J34
N13: VENTAS | Q13: =H34
N14: VENTAS EXENTAS | Q14: =E34
N15: SERVICIOS | Q15: 0
N16: DEBITO FISCAL | Q16: =I34
M19: COSTO DE VENTAS | P19: =ROUND(H34/(1+Parámetros!B6),0)
N20: MERCADERIAS | Q20: =P19
N21: MERCADERIAS EXENTAS | Q21: 0
D34: =SUM(D6:D33) | E34: =SUM(E6:E33) | F34: SUMAS | H34: =SUM(H6:H33) | I34: =SUM(I6:I33) | J34: =SUM(J6:J33)
B36: ( + ) NOTAS DE DEBITO
F49: SUMAS
B51: ( - ) NOTAS DE CREDITO
F64: SUMAS
B71: Resumen de la declaración
B72: 3 VENTAS NETAS | D72: 4 IVA DEBITOS | G72: SUB- TOTAL VENTAS | J72: =J34
B73: =J77 | D73: =J78 | G73: - VENTAS EXENTAS | J73: =E34
B74: 1 COMPRAS AFECTAS | D74: 2 IVA CREDITO | G74: SUMAS DE MES | J74: =J72-J73
B75: ='L. COMPRAS'!H64 | D75: ='L. COMPRAS'!I64 | G75: - NOTAS DE CREDITO (DEVOL.) | J75: =J64
B76: IMPTO DETERMINADO | D76: =MAX(D73-D75-D78,0) | G76: TOTAL VENTAS IVA INCLUI. | J76: =J74-J75
B77: o CREDITO DEL MES | D77: =MAX(D75-D73,0) | G77: TOTAL VENTAS NETAS (3) | J77: =ROUND(J76/(1+I5),0)
B78: -REMANENTE CREDITO ANTERIOR | D78: =E94 | G78: IVA DEBITO VENTAS (4) | J78: =J76-J77
B79: Remanente Mes siguiente | D79: =MAX(D75+D78-D73,0)
B80: Impto. Iva por Pagar | D80: =D76
A81: 0.01 | B81: PPM | C81: =+J77+J73 | D81: =ROUND(C81*A81,0)
B82: RETENCION 2ª CAT. 13,75% | D82: 0
B83: IMPTO. UNICO 2A. CAT. | D83: 0
B84: TOTAL A PAGAR | D84: =D80+D81+D82+D83
B85: CREDITO MES SGTE
B86: UTM MES SIGUIENTE
B87: CREDITO EN UTM
B88: IVA RETENIDO (cambio de sujeto) | D88: ='L. COMPRAS'!K31
...

Sheet Honorarios
B2: LIBRO DE HONORARIOS
B4: N. | C4: Nombre del Profesional | D4: R.U.T. N. | E4: Profesión | F4: Honorario Bruto | G4: Retención | H4: Honorario Líquido
B5: 1
B6: 2
B7: 3
B8: 4
B9: 5
B10: 6
B11: 7
B12: 8
B13: 9
B14: 10
B15: 11
B16: 12
... B24: 20
C28: TOTALES

Sheet FORMULARIO 29
K2: Declaración Mensual y Pago Simultáneo de Impuestos Formulario 29
M4: PERIODO TRIBUTARIO | V4: ROL UNICO TRIBUTARIO | AQ4: FOLIO
M5: 10 | O5: Mes | T5: Año
T6: 2026 | V6: 08 | X6: 76123456 | AM6: =IF(X6>0,IF(AO6=1,"K",IF(AO6=0,"0",11-AO6)),"") | AO6: =IF(X6>0,IF(X6>9999999,MOD((RIGHT(X6,1)*2+LEFT(RIGHT(X6,2),1)*3+LEFT(RIGHT(X6,3),1)*4+LEFT(RIGHT(X6,4),1)*5+LEFT(RIGHT(X6,5),1)*6+LEFT(RIGHT(X6,6),1)*7+LEFT(RIGHT(X6,7),1)*2+LEFT(RIGHT(X6,8),1)*3),11),MOD((RIGHT(X6,1)*2+LEFT(RIGHT(X6,2),1)*3+LEFT(RIGHT(X6,3),1)*4+LEFT(RIGHT(X6,4),1)*5+LEFT(RIGHT(X6,5),1)*6+LEFT(RIGHT(X6,6),1)*7+LEFT(RIGHT(X6,7),1)*2),11)),"") | AQ6: 07
B8: DEBITOS Y VENTAS | D8: IMPUESTO AL VALOR AGREGADO D.L.825/74 | W8: Cantidad de documentos | AN8: Monto Neto
D9: 1 | E9: Ventas y/o Servicios Prestados | F9: No Genera Débito | G9: Exportaciones | W9: 585 | AN9: 20
D10: 2 | G10: Ventas y/o Servicios prestados Internos Exentos, o No Gravados | W10: 586 | AN10: 142
D11: 3 | G11: Ventas con retención sobre el margen de comercialización (contribuyentes retenidos | W11: 731 | AN11: 732
D12: 4 | G12: Ventas y/o Servicios prestados Exentos o No Gravados que no son del giro | W12: 714 | AN12: 715
D13: 5 | G13: Facturas de Compras recibidas con retención total (contribuyentes retenidos) | W13: 515 | AN13: 587
D14: 6 | G14: Facturas de Compras recibidas con retención parcial (Total neto según Línea Nº 14 | AN14: 720
W15: Cantidad de documentos | AN15: Débitos
D16: 7 | F16: Genera Débito | G16: Facturas emitidas | W16: 503 | Y16: =COUNT('L. VENTAS'!C6:C33) | AN16: 502 | AP16: ='L. VENTAS'!I34 | AS16: +
D17: 8 | G17: Facturas y Notas de Débitos por ventas que no son del giro (activo fijo y otros) | W17: 716 | AN17: 717 | AS17: +
D18: 9 | G18: Boletas | W18: 110 | AN18: 111 | AS18: +
D19: 10 | G19: Notas de Débito emitidas | W19: 512 | AN19: 513 | AS19: +
D20: 11 | G20: Notas de Crédito emitidas | W20: 509 | AN20: 510 | AS20: -
D21: 12 | G21: Notas de Crédito emitidas por Vales de máquinas autorizadas por el Servicio | W21: 708 | AN21: 709 | AS21: -
D22: 13 | G22: Notas de Crédito emitidas por ventas y servicios que no son del giro (activo fijo y | W22: 733 | AN22: 734 | AS22: -
D23: 14 | G23: Facturas de Compras recibidas con retención parcial (contribuyentes retenidos) | W23: 516 | AN23: 517 | AS23: +
D24: 15 | G24: Liquidación y Liquidaciones de Facturas | W24: 500 | AN24: 501 | AS24: +
D25: 16 | E25: Adiciones al Débito Fiscal del mes, originadas en devoluciones excesivas registradas en otros períodos por Art. 27 bis | AN25: 154 | AS25: +
D26: 17 | E26: Restitución Adicional por proporción de operaciones exentas y/o no gravadas por concepto Art. 27 bis, inc.2º (Ley 19.738/01) | AN26: 518 | AS26: +
D27: 18 | E27: Reintegro del Impuesto de Timbres y Estampillas Art. 3 Ley Nº20.259 | AN27: 713 | AS27: +
D28: 19 | E28: Adiciones al Débito por IEPD, Ley 20.493 | L28: m3 | M28: 738 | T28: Base | U28: 739 | AD28: Variable | AG28: 740 | AN28: 741 | AS28: +
D29: 20 | E29: TOTAL DEBITOS | AN29: 538 | AP29: =AP16+AP17+AP18+AP19-AP20-AP21-AP22+AP23+AP24+AP25+AP26+AP27+AP28 | AS29: =
B31: CREDITOS Y COMPRAS | D31: IMPUESTO AL VALOR AGREGADO D.L.825/74 | W31: Con Derecho a Crédito | AN31: Sin Derecho a Crédito
D32: 21 | E32: Compras y/o Servicios Utilizados | F32: IVA por documentos electrónicos recibidos | W32: 511 | AN32: 514
W33: Cantidad de documentos | AN33: Monto Neto
D34: 22 | F34: Sin Derecho a Credito Fiscal | H34: Internas afectas | W34: 564 | AN34: 521
D35: 23 | H35: Importaciones | W35: 566 | AN35: 560
D36: 24 | H36: Internas exentas, o no gravadas | W36: 584 | AN36: 562
W37: Cantidad de documentos | AN37: Crédito, Recuperación y Reintegro
D38: 25 | F38: Con Derecho a Crédito Fiscal | G38: Internas | H38: Facturas recibidas del giro y Facturas de compra emitidas | W38: 519 | Y38: =COUNT('L. COMPRAS'!B7:B30) | AN38: 520 | AP38: ='L. COMPRAS'!I31 | AS38: +
D39: 26 | H39: Facturas activo fijo | W39: 524 | AN39: 525 | AS39: +
D40: 27 | H40: Notas de Crédito recibidas | W40: 527 | AN40: 528 | AS40: -
D41: 28 | H41: Notas de Débito recibidas | W41: 531 | AN41: 532 | AS41: +
D42: 29 | G42: Impor-tación | H42: Declaraciones de Ingreso (DIN) importaciones del giro | W42: 534 | AN42: 535 | AS42: +
D43: 30 | H43: Declaraciones de Ingreso (DIN) importaciones activo fijo | W43: 536 | AN43: 553 | AS43: +
D44: 31 | E44: Remanente Crédito Fiscal del mes anterior | AN44: 504 | AP44: ='L. VENTAS'!D78 | AS44: +
...

Sheet UTM
B2: MES | C2: AÑO
C3: 2024 | D3: 2025 | E3: 2026
B4: ENERO | C4: 64666 | D4: 67429 | E4: 69751
B5: FEBRERO | C5: 64343 | D5: 67294 | E5: 69611
B6: MARZO | C6: 64793 | D6: 68034 | E6: 69889
B7: ABRIL | C7: 65182 | D7: 68306 | E7: 69889
B8: MAYO | C8: 65443 | D8: 68648 | E8: 70588
B9: JUNIO | C9: 65770 | D9: 68785 | E9: 71506
B10: JULIO | C10: 65967 | D10: 68923 | E10: 71649
B11: AGOSTO | C11: 65901 | D11: 68647 | E11: 71649
B12: SEPTIEMBRE | C12: 66362 | D12: 69265
B13: OCTUBRE | C13: 66561 | D13: 69265
B14: NOVIEMBRE | C14: 66628 | D14: 69542
B15: DICIEMBRE | C15: 69294 | D15: 69542
B16: ENERO

Sheet Parámetros
A1: Empresa (ficticia) | B1: Silvestres del Ñuble SpA (ficticia)
A2: RUT (ficticio) | B2: 76.123.456-0
A3: Período | B3: Octubre 2026
A4: Tasa de IVA | B4: 0.19
A5: Retención del IVA (1 = total; Res. Ex. SII 4095/2000) | B5: 1
A6: Margen de ganancia sobre el costo | B6: 0.4
A7: Integrantes | B7: Matius Loyola, Diego Quintana, Joaquín Verdejo
A9: Datos inventados. Celdas azules = datos que puedes cambiar; las planillas se recalculan solas.

Sheet Facturas de compra
A1: FACTURAS DE COMPRA (DTE 46) POR CAMBIO DE SUJETO: Silvestres del Ñuble SpA (ficticia)
A4: Folio | B4: Fecha | C4: Proveedor | D4: RUT | E4: Producto | F4: Kilos | G4: Precio por kilo | H4: Neto | I4: IVA 19 % | J4: IVA retenido | K4: IVA que cobra el proveedor | L4: Total a pagar al proveedor
A5: 201 | B5: 46297 | C5: Juan Pérez (recolector) | D5: 11.111.111-1 | E5: Rosa mosqueta | F5: 1200 | G5: 1500 | H5: =F5*G5 | I5: =ROUND(H5*Parámetros!$B$4,0) | J5: =ROUND(I5*Parámetros!$B$5,0) | K5: =I5-J5 | L5: =H5+K5
A6: 202 | B6: 46301 | C6: María Soto (recolectora) | D6: 12.222.222-5 | E6: Hongos | F6: 300 | G6: 4000 | H6: =F6*G6 | I6: =ROUND(H6*Parámetros!$B$4,0) | J6: =ROUND(I6*Parámetros!$B$5,0) | K6: =I6-J6 | L6: =H6+K6
A7: 203 | B7: 46307 | C7: Pedro Núñez (recolector) | D7: 13.333.333-9 | E7: Mora | F7: 500 | G7: 1600 | H7: =F7*G7 | I7: =ROUND(H7*Parámetros!$B$4,0) | J7: =ROUND(I7*Parámetros!$B$5,0) | K7: =I7-J7 | L7: =H7+K7
A8: 204 | B8: 46314 | C8: Rosa Muñoz (recolectora) | D8: 14.444.444-2 | E8: Hojas de boldo | F8: 400 | G8: 1250 | H8: =F8*G8 | I8: =ROUND(H8*Parámetros!$B$4,0) | J8: =ROUND(I8*Parámetros!$B$5,0) | K8: =I8-J8 | L8: =H8+K8
A9: 205 | B9: 46321 | C9: Luis Araya (recolector) | D9: 15.555.555-6 | E9: Frutos de espino | F9: 900 | G9: 1500 | H9: =F9*G9 | I9: =ROUND(H9*Parámetros!$B$4,0) | J9: =ROUND(I9*Parámetros!$B$5,0) | K9: =I9-J9 | L9: =H9+K9
A10: TOTAL | H10: =SUM(H5:H9) | I10: =SUM(I5:I9) | J10: =SUM(J5:J9) | K10: =SUM(K5:K9) | L10: =SUM(L5:L9)

Sheet Libro diario
A1: Asiento | B1: Fecha | C1: Cuenta | D1: Glosa | E1: Debe | F1: Haber
A2: 1 | B2: 46297 | C2: 1.1.13 Inventario mercaderías | D2: Factura de compra N°201: Rosa mosqueta (IVA retenido) | E2: ='L. COMPRAS'!H7
A3: 1 | B3: 46297 | C3: 1.1.04 IVA crédito fiscal | D3: Factura de compra N°201: Rosa mosqueta (IVA retenido) | E3: ='L. COMPRAS'!I7
A4: 1 | B4: 46297 | C4: 2.1.01 Proveedores | D4: Factura de compra N°201: Rosa mosqueta (IVA retenido) | F4: ='L. COMPRAS'!J7-'L. COMPRAS'!K7
A5: 1 | B5: 46297 | C5: 2.1.09 IVA retenido por pagar | D5: Factura de compra N°201: Rosa mosqueta (IVA retenido) | F5: ='L. COMPRAS'!K7
A6: 2 | B6: 46301 | C6: 1.1.13 Inventario mercaderías | D6: Factura de compra N°202: Hongos (IVA retenido) | E6: ='L. COMPRAS'!H8
A7: 2 | B7: 46301 | C7: 1.1.04 IVA crédito fiscal | D7: Factura de compra N°202: Hongos (IVA retenido) | E7: ='L. COMPRAS'!I8
A8: 2 | B8: 46301 | C8: 2.1.01 Proveedores | D8: Factura de compra N°202: Hongos (IVA retenido) | F8: ='L. COMPRAS'!J8-'L. COMPRAS'!K8
A9: 2 | B9: 46301 | C9: 2.1.09 IVA retenido por pagar | D9: Factura de compra N°202: Hongos (IVA retenido) | F9: ='L. COMPRAS'!K8
A10: 3 | B10: 46307 | C10: 1.1.13 Inventario mercaderías | D10: Factura de compra N°203: Mora (IVA retenido) | E10: ='L. COMPRAS'!H9
A11: 3 | B11: 46307 | C11: 1.1.04 IVA crédito fiscal | D11: Factura de compra N°203: Mora (IVA retenido) | E11: ='L. COMPRAS'!I9
A12: 3 | B12: 46307 | C12: 2.1.01 Proveedores | D12: Factura de compra N°203: Mora (IVA retenido) | F12: ='L. COMPRAS'!J9-'L. COMPRAS'!K9
A13: 3 | B13: 46307 | C13: 2.1.09 IVA retenido por pagar | D13: Factura de compra N°203: Mora (IVA retenido) | F13: ='L. COMPRAS'!K9
A14: 4 | B14: 46314 | C14: 1.1.13 Inventario mercaderías | D14: Factura de compra N°204: Hojas de boldo (IVA retenido) | E14: ='L. COMPRAS'!H10
A15: 4 | B15: 46314 | C15: 1.1.04 IVA crédito fiscal | D15: Factura de compra N°204: Hojas de boldo (IVA retenido) | E15: ='L. COMPRAS'!I10
A16: 4 | B16: 46314 | C16: 2.1.01 Proveedores | D16: Factura de compra N°204: Hojas de boldo (IVA retenido) | F16: ='L. COMPRAS'!J10-'L. COMPRAS'!K10
A17: 4 | B17: 46314 | C17: 2.1.09 IVA retenido por pagar | D17: Factura de compra N°204: Hojas de boldo (IVA retenido) | F17: ='L. COMPRAS'!K10
A18: 5 | B18: 46321 | C18: 1.1.13 Inventario mercaderías | D18: Factura de compra N°205: Frutos de espino (IVA retenido) | E18: ='L. COMPRAS'!H11
A19: 5 | B19: 46321 | C19: 1.1.04 IVA crédito fiscal | D19: Factura de compra N°205: Frutos de espino (IVA retenido) | E19: ='L. COMPRAS'!I11
A20: 5 | B20: 46321 | C20: 2.1.01 Proveedores | D20: Factura de compra N°205: Frutos de espino (IVA retenido) | F20: ='L. COMPRAS'!J11-'L. COMPRAS'!K11
A21: 5 | B21: 46321 | C21: 2.1.09 IVA retenido por pagar | D21: Factura de compra N°205: Frutos de espino (IVA retenido) | F21: ='L. COMPRAS'!K11
A22: 6 | B22: 46300 | C22: 1.1.03 Clientes | D22: Factura de venta N°101 a Exportadora Andes SpA | E22: ='L. VENTAS'!J6
A23: 6 | B23: 46300 | C23: 4.1.01 Ventas | D23: Factura de venta N°101 a Exportadora Andes SpA | F23: ='L. VENTAS'!H6
A24: 6 | B24: 46300 | C24: 2.1.02 IVA débito fiscal | D24: Factura de venta N°101 a Exportadora Andes SpA | F24: ='L. VENTAS'!I6
A25: 7 | B25: 46304 | C25: 1.1.03 Clientes | D25: Factura de venta N°102 a Agroindustrial Sur Ltda. | E25: ='L. VENTAS'!J7
A26: 7 | B26: 46304 | C26: 4.1.01 Ventas | D26: Factura de venta N°102 a Agroindustrial Sur Ltda. | F26: ='L. VENTAS'!H7
A27: 7 | B27: 46304 | C27: 2.1.02 IVA débito fiscal | D27: Factura de venta N°102 a Agroindustrial Sur Ltda. | F27: ='L. VENTAS'!I7
A28: 8 | B28: 46309 | C28: 1.1.03 Clientes | D28: Factura de venta N°103 a Hierbas del Valle S.A. | E28: ='L. VENTAS'!J8
A29: 8 | B29: 46309 | C29: 4.1.01 Ventas | D29: Factura de venta N°103 a Hierbas del Valle S.A. | F29: ='L. VENTAS'!H8
A30: 8 | B30: 46309 | C30: 2.1.02 IVA débito fiscal | D30: Factura de venta N°103 a Hierbas del Valle S.A. | F30: ='L. VENTAS'!I8
A31: 9 | B31: 46316 | C31: 1.1.03 Clientes | D31: Factura de venta N°104 a Comercial Maule SpA | E31: ='L. VENTAS'!J9
A32: 9 | B32: 46316 | C32: 4.1.01 Ventas | D32: Factura de venta N°104 a Comercial Maule SpA | F32: ='L. VENTAS'!H9
A33: 9 | B33: 46316 | C33: 2.1.02 IVA débito fiscal | D33: Factura de venta N°104 a Comercial Maule SpA | F33: ='L. VENTAS'!I9
A34: 10 | B34: 46323 | C34: 1.1.03 Clientes | D34: Factura de venta N°105 a Distribuidora Bío Bío Ltda. | E34: ='L. VENTAS'!J10
A35: 10 | B35: 46323 | C35: 4.1.01 Ventas | D35: Factura de venta N°105 a Distribuidora Bío Bío Ltda. | F35: ='L. VENTAS'!H10
A36: 10 | B36: 46323 | C36: 2.1.02 IVA débito fiscal | D36: Factura de venta N°105 a Distribuidora Bío Bío Ltda. | F36: ='L. VENTAS'!I10
A37: 11 | B37: 46326 | C37: 5.1.01 Costo de ventas | D37: Costo de las ventas del mes | E37: ='L. VENTAS'!P19
A38: 11 | B38: 46326 | C38: 1.1.13 Inventario mercaderías | D38: Costo de las ventas del mes | F38: ='L. VENTAS'!P19
A39: 12 | B39: 46326 | C39: 2.1.01 Proveedores | D39: Pago a los proveedores | E39: ='L. COMPRAS'!O16
A40: 12 | B40: 46326 | C40: 1.1.02 Banco | D40: Pago a los proveedores | F40: ='L. COMPRAS'!O16
...

Sheet DJ F3500
A1: DECLARACIÓN JURADA F3500: informe mensual de retenedores de cambio de sujeto de IVA
A2: Contribuyente: Silvestres del Ñuble SpA (ficticia), RUT 76.123.456-0 · Período: Octubre 2026 · Plazo: hasta el día 15 del mes siguiente (si no es hábil, el día hábil siguiente: 16-11-2026). Se presenta aunque no haya movimiento.
A4: RUT del vendedor (retenido) | B4: Código de producto (F3500) | C4: Producto | D4: Tipo de documento | E4: N° documento | F4: Fecha | G4: Cantidad | H4: Unidad de medida (cód. 1) | I4: IVA retenido total
A5: ='L. COMPRAS'!D7 | B5: 3101 | C5: Rosa mosqueta | D5: 46 Factura de compra electrónica | E5: ='L. COMPRAS'!B7 | F5: ='L. COMPRAS'!A7 | G5: ='Facturas de compra'!F5 | H5: 1 | I5: ='L. COMPRAS'!K7
A6: ='L. COMPRAS'!D8 | B6: 3103 | C6: Hongos | D6: 46 Factura de compra electrónica | E6: ='L. COMPRAS'!B8 | F6: ='L. COMPRAS'!A8 | G6: ='Facturas de compra'!F6 | H6: 1 | I6: ='L. COMPRAS'!K8
A7: ='L. COMPRAS'!D9 | B7: 3102 | C7: Mora | D7: 46 Factura de compra electrónica | E7: ='L. COMPRAS'!B9 | F7: ='L. COMPRAS'!A9 | G7: ='Facturas de compra'!F7 | H7: 1 | I7: ='L. COMPRAS'!K9
A8: ='L. COMPRAS'!D10 | B8: 3105 | C8: Hojas de boldo | D8: 46 Factura de compra electrónica | E8: ='L. COMPRAS'!B10 | F8: ='L. COMPRAS'!A10 | G8: ='Facturas de compra'!F8 | H8: 1 | I8: ='L. COMPRAS'!K10
A9: ='L. COMPRAS'!D11 | B9: 3104 | C9: Frutos de espino | D9: 46 Factura de compra electrónica | E9: ='L. COMPRAS'!B11 | F9: ='L. COMPRAS'!A11 | G9: ='Facturas de compra'!F9 | H9: 1 | I9: ='L. COMPRAS'!K11
A10: TOTAL | I10: =SUM(I5:I9)
A12: Se informa operación por operación. Los facturadores electrónicos que documentan todo por ese medio y envían su libro de compras y ventas no están obligados a presentarla; aquí se presenta porque el profesor la pide. ⚠️ Verificar el formato vigente en sii.cl.
